<mujoco model="bottle_cap_template">

    <include file="./shared_xml/shared_assets.xml" />

    <worldbody>
        
<!--        <body name="shadow_hand" pos="-0.02 -0.1 0.11" euler="-1.57 0 0">-->
<!--            <include file="./shared_xml/right_hand.xml" />-->
<!--        </body>-->
        <body name="shadow_hand" pos="-0.03 0 0.24" euler="3.14 0 0">
            <include file="./shared_xml/right_hand.xml" />
        </body>
        <body name="bottle_cap" pos="0 0 0.1535">    #0.1635    0.275
            <joint axis="0 0 1" damping="0.5" limited="false" name="OBJRz" pos="0 0 0" />
<!--        <geom name="cap" mesh="core-bottle-1a7ba1f4c892e2da30711cdbdbc73924-coacd_convex_piece_0" mass="0.01" pos="0 0 0" rgba="0.3 0.6 0.6 1" type="mesh" condim="6" friction="0.5 0.01 0.003" /></body>-->
            <geom name="cap" type="cylinder" size="0.06 0.01" condim="6" priority="1" friction="0.5 0.01 0.003" rgba="0.3 0.6 0.6 1"/>
            <site name="mark" pos="-0.05 0 0.01" rgba="0.8 0.2 0.3 1"  size="0.007" euler="-1.57 0 0"/>
        </body>
        <body name="bottle" pos="0 0 0.0820382">
            <geom name="coacd_convex_piece_1" mesh="core-bottle-1a7ba1f4c892e2da30711cdbdbc73924-coacd_convex_piece_1" mass="0.01" pos="0 0 0" rgba="0.6 0.2 0.2 1" type="mesh"  /><geom name="coacd_convex_piece_2" mesh="core-bottle-1a7ba1f4c892e2da30711cdbdbc73924-coacd_convex_piece_2" mass="0.01" pos="0 0 0" rgba="0.6 0.2 0.2 1" type="mesh" contype="2" conaffinity="2" /><geom name="coacd_convex_piece_3" mesh="core-bottle-1a7ba1f4c892e2da30711cdbdbc73924-coacd_convex_piece_3" mass="0.01" pos="0 0 0" rgba="0.6 0.2 0.2 1" type="mesh" contype="2" conaffinity="2" /></body>

    </worldbody>

<!--    <actuator>-->
<!--        <position name="a_cap" joint="OBJRz" ctrlrange="-7 7"/>-->
<!--    </actuator>-->

<asset><mesh name="core-bottle-1a7ba1f4c892e2da30711cdbdbc73924-coacd_convex_piece_0" file="core-bottle-1a7ba1f4c892e2da30711cdbdbc73924-coacd_convex_piece_0.obj" scale="0.1 0.1 0.1" /><mesh name="core-bottle-1a7ba1f4c892e2da30711cdbdbc73924-coacd_convex_piece_1" file="core-bottle-1a7ba1f4c892e2da30711cdbdbc73924-coacd_convex_piece_1.obj" scale="0.1 0.1 0.1" /><mesh name="core-bottle-1a7ba1f4c892e2da30711cdbdbc73924-coacd_convex_piece_2" file="core-bottle-1a7ba1f4c892e2da30711cdbdbc73924-coacd_convex_piece_2.obj" scale="0.1 0.1 0.1" /><mesh name="core-bottle-1a7ba1f4c892e2da30711cdbdbc73924-coacd_convex_piece_3" file="core-bottle-1a7ba1f4c892e2da30711cdbdbc73924-coacd_convex_piece_3.obj" scale="0.1 0.1 0.1" /></asset></mujoco>
