<mujoco model="bottle_cap_template">

    <include file="./shared_xml/shared_assets.xml" />

    <worldbody>
        
        <body name="shadow_hand" pos="-0.35 -0.03 0.23322510000000002" euler="3.1415 0 0">
            <include file="./shared_xml/right_hand.xml" />
        </body>
        
        <body name="bottle_cap" pos="0 0 0.0816121">
            <joint axis="0 0 1" damping="0.05" limited="false" name="OBJRz" pos="0 0 0" />
        <geom name="cap" mesh="core-bottle-42f85b0eb5e9fd508f9c4ecc067067e9-coacd_convex_piece_2" mass="0.01" pos="0 0 0" rgba="0.3 0.6 0.6 1" type="mesh" condim="6" priority="1" friction="0.5 0.01 0.003" /></body>
        
        <body name="bottle" pos="0 0 0.0816121">
            <geom name="coacd_convex_piece_12" mesh="core-bottle-42f85b0eb5e9fd508f9c4ecc067067e9-coacd_convex_piece_12" mass="0.01" pos="0 0 0" rgba="0.6 0.2 0.2 1" type="mesh" contype="2" conaffinity="2" /><geom name="coacd_convex_piece_13" mesh="core-bottle-42f85b0eb5e9fd508f9c4ecc067067e9-coacd_convex_piece_13" mass="0.01" pos="0 0 0" rgba="0.6 0.2 0.2 1" type="mesh" contype="2" conaffinity="2" /><geom name="coacd_convex_piece_19" mesh="core-bottle-42f85b0eb5e9fd508f9c4ecc067067e9-coacd_convex_piece_19" mass="0.01" pos="0 0 0" rgba="0.6 0.2 0.2 1" type="mesh" contype="2" conaffinity="2" /><geom name="coacd_convex_piece_11" mesh="core-bottle-42f85b0eb5e9fd508f9c4ecc067067e9-coacd_convex_piece_11" mass="0.01" pos="0 0 0" rgba="0.6 0.2 0.2 1" type="mesh" contype="2" conaffinity="2" /><geom name="coacd_convex_piece_14" mesh="core-bottle-42f85b0eb5e9fd508f9c4ecc067067e9-coacd_convex_piece_14" mass="0.01" pos="0 0 0" rgba="0.6 0.2 0.2 1" type="mesh" contype="2" conaffinity="2" /><geom name="coacd_convex_piece_17" mesh="core-bottle-42f85b0eb5e9fd508f9c4ecc067067e9-coacd_convex_piece_17" mass="0.01" pos="0 0 0" rgba="0.6 0.2 0.2 1" type="mesh" contype="2" conaffinity="2" /><geom name="coacd_convex_piece_22" mesh="core-bottle-42f85b0eb5e9fd508f9c4ecc067067e9-coacd_convex_piece_22" mass="0.01" pos="0 0 0" rgba="0.6 0.2 0.2 1" type="mesh" contype="2" conaffinity="2" /><geom name="coacd_convex_piece_4" mesh="core-bottle-42f85b0eb5e9fd508f9c4ecc067067e9-coacd_convex_piece_4" mass="0.01" pos="0 0 0" rgba="0.6 0.2 0.2 1" type="mesh" contype="2" conaffinity="2" /><geom name="coacd_convex_piece_8" mesh="core-bottle-42f85b0eb5e9fd508f9c4ecc067067e9-coacd_convex_piece_8" mass="0.01" pos="0 0 0" rgba="0.6 0.2 0.2 1" type="mesh" contype="2" conaffinity="2" /><geom name="coacd_convex_piece_1" mesh="core-bottle-42f85b0eb5e9fd508f9c4ecc067067e9-coacd_convex_piece_1" mass="0.01" pos="0 0 0" rgba="0.6 0.2 0.2 1" type="mesh" contype="2" conaffinity="2" /><geom name="coacd_convex_piece_20" mesh="core-bottle-42f85b0eb5e9fd508f9c4ecc067067e9-coacd_convex_piece_20" mass="0.01" pos="0 0 0" rgba="0.6 0.2 0.2 1" type="mesh" contype="2" conaffinity="2" /><geom name="coacd_convex_piece_16" mesh="core-bottle-42f85b0eb5e9fd508f9c4ecc067067e9-coacd_convex_piece_16" mass="0.01" pos="0 0 0" rgba="0.6 0.2 0.2 1" type="mesh" contype="2" conaffinity="2" /><geom name="coacd_convex_piece_3" mesh="core-bottle-42f85b0eb5e9fd508f9c4ecc067067e9-coacd_convex_piece_3" mass="0.01" pos="0 0 0" rgba="0.6 0.2 0.2 1" type="mesh" contype="2" conaffinity="2" /><geom name="coacd_convex_piece_6" mesh="core-bottle-42f85b0eb5e9fd508f9c4ecc067067e9-coacd_convex_piece_6" mass="0.01" pos="0 0 0" rgba="0.6 0.2 0.2 1" type="mesh" contype="2" conaffinity="2" /><geom name="coacd_convex_piece_7" mesh="core-bottle-42f85b0eb5e9fd508f9c4ecc067067e9-coacd_convex_piece_7" mass="0.01" pos="0 0 0" rgba="0.6 0.2 0.2 1" type="mesh" contype="2" conaffinity="2" /><geom name="coacd_convex_piece_9" mesh="core-bottle-42f85b0eb5e9fd508f9c4ecc067067e9-coacd_convex_piece_9" mass="0.01" pos="0 0 0" rgba="0.6 0.2 0.2 1" type="mesh" contype="2" conaffinity="2" /><geom name="coacd_convex_piece_0" mesh="core-bottle-42f85b0eb5e9fd508f9c4ecc067067e9-coacd_convex_piece_0" mass="0.01" pos="0 0 0" rgba="0.6 0.2 0.2 1" type="mesh" contype="2" conaffinity="2" /><geom name="coacd_convex_piece_5" mesh="core-bottle-42f85b0eb5e9fd508f9c4ecc067067e9-coacd_convex_piece_5" mass="0.01" pos="0 0 0" rgba="0.6 0.2 0.2 1" type="mesh" contype="2" conaffinity="2" /><geom name="coacd_convex_piece_18" mesh="core-bottle-42f85b0eb5e9fd508f9c4ecc067067e9-coacd_convex_piece_18" mass="0.01" pos="0 0 0" rgba="0.6 0.2 0.2 1" type="mesh" contype="2" conaffinity="2" /><geom name="coacd_convex_piece_15" mesh="core-bottle-42f85b0eb5e9fd508f9c4ecc067067e9-coacd_convex_piece_15" mass="0.01" pos="0 0 0" rgba="0.6 0.2 0.2 1" type="mesh" contype="2" conaffinity="2" /><geom name="coacd_convex_piece_21" mesh="core-bottle-42f85b0eb5e9fd508f9c4ecc067067e9-coacd_convex_piece_21" mass="0.01" pos="0 0 0" rgba="0.6 0.2 0.2 1" type="mesh" contype="2" conaffinity="2" /><geom name="coacd_convex_piece_10" mesh="core-bottle-42f85b0eb5e9fd508f9c4ecc067067e9-coacd_convex_piece_10" mass="0.01" pos="0 0 0" rgba="0.6 0.2 0.2 1" type="mesh" contype="2" conaffinity="2" /></body>

    </worldbody>



<asset><mesh name="core-bottle-42f85b0eb5e9fd508f9c4ecc067067e9-coacd_convex_piece_2" file="core-bottle-42f85b0eb5e9fd508f9c4ecc067067e9-coacd_convex_piece_2.obj" scale="0.1 0.1 0.1" /><mesh name="core-bottle-42f85b0eb5e9fd508f9c4ecc067067e9-coacd_convex_piece_12" file="core-bottle-42f85b0eb5e9fd508f9c4ecc067067e9-coacd_convex_piece_12.obj" scale="0.1 0.1 0.1" /><mesh name="core-bottle-42f85b0eb5e9fd508f9c4ecc067067e9-coacd_convex_piece_13" file="core-bottle-42f85b0eb5e9fd508f9c4ecc067067e9-coacd_convex_piece_13.obj" scale="0.1 0.1 0.1" /><mesh name="core-bottle-42f85b0eb5e9fd508f9c4ecc067067e9-coacd_convex_piece_19" file="core-bottle-42f85b0eb5e9fd508f9c4ecc067067e9-coacd_convex_piece_19.obj" scale="0.1 0.1 0.1" /><mesh name="core-bottle-42f85b0eb5e9fd508f9c4ecc067067e9-coacd_convex_piece_11" file="core-bottle-42f85b0eb5e9fd508f9c4ecc067067e9-coacd_convex_piece_11.obj" scale="0.1 0.1 0.1" /><mesh name="core-bottle-42f85b0eb5e9fd508f9c4ecc067067e9-coacd_convex_piece_14" file="core-bottle-42f85b0eb5e9fd508f9c4ecc067067e9-coacd_convex_piece_14.obj" scale="0.1 0.1 0.1" /><mesh name="core-bottle-42f85b0eb5e9fd508f9c4ecc067067e9-coacd_convex_piece_17" file="core-bottle-42f85b0eb5e9fd508f9c4ecc067067e9-coacd_convex_piece_17.obj" scale="0.1 0.1 0.1" /><mesh name="core-bottle-42f85b0eb5e9fd508f9c4ecc067067e9-coacd_convex_piece_22" file="core-bottle-42f85b0eb5e9fd508f9c4ecc067067e9-coacd_convex_piece_22.obj" scale="0.1 0.1 0.1" /><mesh name="core-bottle-42f85b0eb5e9fd508f9c4ecc067067e9-coacd_convex_piece_4" file="core-bottle-42f85b0eb5e9fd508f9c4ecc067067e9-coacd_convex_piece_4.obj" scale="0.1 0.1 0.1" /><mesh name="core-bottle-42f85b0eb5e9fd508f9c4ecc067067e9-coacd_convex_piece_8" file="core-bottle-42f85b0eb5e9fd508f9c4ecc067067e9-coacd_convex_piece_8.obj" scale="0.1 0.1 0.1" /><mesh name="core-bottle-42f85b0eb5e9fd508f9c4ecc067067e9-coacd_convex_piece_1" file="core-bottle-42f85b0eb5e9fd508f9c4ecc067067e9-coacd_convex_piece_1.obj" scale="0.1 0.1 0.1" /><mesh name="core-bottle-42f85b0eb5e9fd508f9c4ecc067067e9-coacd_convex_piece_20" file="core-bottle-42f85b0eb5e9fd508f9c4ecc067067e9-coacd_convex_piece_20.obj" scale="0.1 0.1 0.1" /><mesh name="core-bottle-42f85b0eb5e9fd508f9c4ecc067067e9-coacd_convex_piece_16" file="core-bottle-42f85b0eb5e9fd508f9c4ecc067067e9-coacd_convex_piece_16.obj" scale="0.1 0.1 0.1" /><mesh name="core-bottle-42f85b0eb5e9fd508f9c4ecc067067e9-coacd_convex_piece_3" file="core-bottle-42f85b0eb5e9fd508f9c4ecc067067e9-coacd_convex_piece_3.obj" scale="0.1 0.1 0.1" /><mesh name="core-bottle-42f85b0eb5e9fd508f9c4ecc067067e9-coacd_convex_piece_6" file="core-bottle-42f85b0eb5e9fd508f9c4ecc067067e9-coacd_convex_piece_6.obj" scale="0.1 0.1 0.1" /><mesh name="core-bottle-42f85b0eb5e9fd508f9c4ecc067067e9-coacd_convex_piece_7" file="core-bottle-42f85b0eb5e9fd508f9c4ecc067067e9-coacd_convex_piece_7.obj" scale="0.1 0.1 0.1" /><mesh name="core-bottle-42f85b0eb5e9fd508f9c4ecc067067e9-coacd_convex_piece_9" file="core-bottle-42f85b0eb5e9fd508f9c4ecc067067e9-coacd_convex_piece_9.obj" scale="0.1 0.1 0.1" /><mesh name="core-bottle-42f85b0eb5e9fd508f9c4ecc067067e9-coacd_convex_piece_0" file="core-bottle-42f85b0eb5e9fd508f9c4ecc067067e9-coacd_convex_piece_0.obj" scale="0.1 0.1 0.1" /><mesh name="core-bottle-42f85b0eb5e9fd508f9c4ecc067067e9-coacd_convex_piece_5" file="core-bottle-42f85b0eb5e9fd508f9c4ecc067067e9-coacd_convex_piece_5.obj" scale="0.1 0.1 0.1" /><mesh name="core-bottle-42f85b0eb5e9fd508f9c4ecc067067e9-coacd_convex_piece_18" file="core-bottle-42f85b0eb5e9fd508f9c4ecc067067e9-coacd_convex_piece_18.obj" scale="0.1 0.1 0.1" /><mesh name="core-bottle-42f85b0eb5e9fd508f9c4ecc067067e9-coacd_convex_piece_15" file="core-bottle-42f85b0eb5e9fd508f9c4ecc067067e9-coacd_convex_piece_15.obj" scale="0.1 0.1 0.1" /><mesh name="core-bottle-42f85b0eb5e9fd508f9c4ecc067067e9-coacd_convex_piece_21" file="core-bottle-42f85b0eb5e9fd508f9c4ecc067067e9-coacd_convex_piece_21.obj" scale="0.1 0.1 0.1" /><mesh name="core-bottle-42f85b0eb5e9fd508f9c4ecc067067e9-coacd_convex_piece_10" file="core-bottle-42f85b0eb5e9fd508f9c4ecc067067e9-coacd_convex_piece_10.obj" scale="0.1 0.1 0.1" /></asset></mujoco>