<mujoco model="bottle_cap_template">

    <include file="./shared_xml/shared_assets.xml" />

    <worldbody>
        
        <body name="shadow_hand" pos="-0.35 -0.03 0.25784260000000003" euler="3.1415 0 0">
            <include file="./shared_xml/right_hand.xml" />
        </body>
        
        <body name="bottle_cap" pos="0 0 0.0939213">
            <joint axis="0 0 1" damping="0.05" limited="false" name="OBJRz" pos="0 0 0" />
        <geom name="cap" mesh="core-bottle-dc9247034a68285efea8a3df5e20f054-coacd_convex_piece_1" mass="0.01" pos="0 0 0" rgba="0.3 0.6 0.6 1" type="mesh" condim="6" priority="1" friction="0.5 0.01 0.003" /></body>
        
        <body name="bottle" pos="0 0 0.0939213">
            <geom name="coacd_convex_piece_12" mesh="core-bottle-dc9247034a68285efea8a3df5e20f054-coacd_convex_piece_12" mass="0.01" pos="0 0 0" rgba="0.6 0.2 0.2 1" type="mesh" contype="2" conaffinity="2" /><geom name="coacd_convex_piece_11" mesh="core-bottle-dc9247034a68285efea8a3df5e20f054-coacd_convex_piece_11" mass="0.01" pos="0 0 0" rgba="0.6 0.2 0.2 1" type="mesh" contype="2" conaffinity="2" /><geom name="coacd_convex_piece_4" mesh="core-bottle-dc9247034a68285efea8a3df5e20f054-coacd_convex_piece_4" mass="0.01" pos="0 0 0" rgba="0.6 0.2 0.2 1" type="mesh" contype="2" conaffinity="2" /><geom name="coacd_convex_piece_8" mesh="core-bottle-dc9247034a68285efea8a3df5e20f054-coacd_convex_piece_8" mass="0.01" pos="0 0 0" rgba="0.6 0.2 0.2 1" type="mesh" contype="2" conaffinity="2" /><geom name="coacd_convex_piece_2" mesh="core-bottle-dc9247034a68285efea8a3df5e20f054-coacd_convex_piece_2" mass="0.01" pos="0 0 0" rgba="0.6 0.2 0.2 1" type="mesh" contype="2" conaffinity="2" /><geom name="coacd_convex_piece_3" mesh="core-bottle-dc9247034a68285efea8a3df5e20f054-coacd_convex_piece_3" mass="0.01" pos="0 0 0" rgba="0.6 0.2 0.2 1" type="mesh" contype="2" conaffinity="2" /><geom name="coacd_convex_piece_6" mesh="core-bottle-dc9247034a68285efea8a3df5e20f054-coacd_convex_piece_6" mass="0.01" pos="0 0 0" rgba="0.6 0.2 0.2 1" type="mesh" contype="2" conaffinity="2" /><geom name="coacd_convex_piece_7" mesh="core-bottle-dc9247034a68285efea8a3df5e20f054-coacd_convex_piece_7" mass="0.01" pos="0 0 0" rgba="0.6 0.2 0.2 1" type="mesh" contype="2" conaffinity="2" /><geom name="coacd_convex_piece_9" mesh="core-bottle-dc9247034a68285efea8a3df5e20f054-coacd_convex_piece_9" mass="0.01" pos="0 0 0" rgba="0.6 0.2 0.2 1" type="mesh" contype="2" conaffinity="2" /><geom name="coacd_convex_piece_0" mesh="core-bottle-dc9247034a68285efea8a3df5e20f054-coacd_convex_piece_0" mass="0.01" pos="0 0 0" rgba="0.6 0.2 0.2 1" type="mesh" contype="2" conaffinity="2" /><geom name="coacd_convex_piece_5" mesh="core-bottle-dc9247034a68285efea8a3df5e20f054-coacd_convex_piece_5" mass="0.01" pos="0 0 0" rgba="0.6 0.2 0.2 1" type="mesh" contype="2" conaffinity="2" /><geom name="coacd_convex_piece_10" mesh="core-bottle-dc9247034a68285efea8a3df5e20f054-coacd_convex_piece_10" mass="0.01" pos="0 0 0" rgba="0.6 0.2 0.2 1" type="mesh" contype="2" conaffinity="2" /></body>

    </worldbody>



<asset><mesh name="core-bottle-dc9247034a68285efea8a3df5e20f054-coacd_convex_piece_1" file="core-bottle-dc9247034a68285efea8a3df5e20f054-coacd_convex_piece_1.obj" scale="0.1 0.1 0.1" /><mesh name="core-bottle-dc9247034a68285efea8a3df5e20f054-coacd_convex_piece_12" file="core-bottle-dc9247034a68285efea8a3df5e20f054-coacd_convex_piece_12.obj" scale="0.1 0.1 0.1" /><mesh name="core-bottle-dc9247034a68285efea8a3df5e20f054-coacd_convex_piece_11" file="core-bottle-dc9247034a68285efea8a3df5e20f054-coacd_convex_piece_11.obj" scale="0.1 0.1 0.1" /><mesh name="core-bottle-dc9247034a68285efea8a3df5e20f054-coacd_convex_piece_4" file="core-bottle-dc9247034a68285efea8a3df5e20f054-coacd_convex_piece_4.obj" scale="0.1 0.1 0.1" /><mesh name="core-bottle-dc9247034a68285efea8a3df5e20f054-coacd_convex_piece_8" file="core-bottle-dc9247034a68285efea8a3df5e20f054-coacd_convex_piece_8.obj" scale="0.1 0.1 0.1" /><mesh name="core-bottle-dc9247034a68285efea8a3df5e20f054-coacd_convex_piece_2" file="core-bottle-dc9247034a68285efea8a3df5e20f054-coacd_convex_piece_2.obj" scale="0.1 0.1 0.1" /><mesh name="core-bottle-dc9247034a68285efea8a3df5e20f054-coacd_convex_piece_3" file="core-bottle-dc9247034a68285efea8a3df5e20f054-coacd_convex_piece_3.obj" scale="0.1 0.1 0.1" /><mesh name="core-bottle-dc9247034a68285efea8a3df5e20f054-coacd_convex_piece_6" file="core-bottle-dc9247034a68285efea8a3df5e20f054-coacd_convex_piece_6.obj" scale="0.1 0.1 0.1" /><mesh name="core-bottle-dc9247034a68285efea8a3df5e20f054-coacd_convex_piece_7" file="core-bottle-dc9247034a68285efea8a3df5e20f054-coacd_convex_piece_7.obj" scale="0.1 0.1 0.1" /><mesh name="core-bottle-dc9247034a68285efea8a3df5e20f054-coacd_convex_piece_9" file="core-bottle-dc9247034a68285efea8a3df5e20f054-coacd_convex_piece_9.obj" scale="0.1 0.1 0.1" /><mesh name="core-bottle-dc9247034a68285efea8a3df5e20f054-coacd_convex_piece_0" file="core-bottle-dc9247034a68285efea8a3df5e20f054-coacd_convex_piece_0.obj" scale="0.1 0.1 0.1" /><mesh name="core-bottle-dc9247034a68285efea8a3df5e20f054-coacd_convex_piece_5" file="core-bottle-dc9247034a68285efea8a3df5e20f054-coacd_convex_piece_5.obj" scale="0.1 0.1 0.1" /><mesh name="core-bottle-dc9247034a68285efea8a3df5e20f054-coacd_convex_piece_10" file="core-bottle-dc9247034a68285efea8a3df5e20f054-coacd_convex_piece_10.obj" scale="0.1 0.1 0.1" /></asset></mujoco>