<robot name="root">
  <link name="body">
    <visual>
      <origin xyz="0 0 0" rpy="0 0 0"/>
      <geometry>
        <mesh filename="coacd_convex_piece_0.obj" scale="1.0000E+00 1.0000E+00 1.0000E+00"/>
      </geometry>
      <material name="">
        <color rgba="7.50E-01 7.50E-01 7.50E-01 1"/>
      </material>
    </visual>
    <collision>
      <origin xyz="0 0 0" rpy="0 0 0"/>
      <geometry>
        <mesh filename="coacd_convex_piece_0.obj" scale="1.0000E+00 1.0000E+00 1.0000E+00"/>
      </geometry>
    </collision>
    <visual>
      <origin xyz="0 0 0" rpy="0 0 0"/>
      <geometry>
        <mesh filename="coacd_convex_piece_1.obj" scale="1.0000E+00 1.0000E+00 1.0000E+00"/>
      </geometry>
      <material name="">
        <color rgba="7.50E-01 7.50E-01 7.50E-01 1"/>
      </material>
    </visual>
    <collision>
      <origin xyz="0 0 0" rpy="0 0 0"/>
      <geometry>
        <mesh filename="coacd_convex_piece_1.obj" scale="1.0000E+00 1.0000E+00 1.0000E+00"/>
      </geometry>
    </collision>
    <visual>
      <origin xyz="0 0 0" rpy="0 0 0"/>
      <geometry>
        <mesh filename="coacd_convex_piece_2.obj" scale="1.0000E+00 1.0000E+00 1.0000E+00"/>
      </geometry>
      <material name="">
        <color rgba="7.50E-01 7.50E-01 7.50E-01 1"/>
      </material>
    </visual>
    <collision>
      <origin xyz="0 0 0" rpy="0 0 0"/>
      <geometry>
        <mesh filename="coacd_convex_piece_2.obj" scale="1.0000E+00 1.0000E+00 1.0000E+00"/>
      </geometry>
    </collision>
    <visual>
      <origin xyz="0 0 0" rpy="0 0 0"/>
      <geometry>
        <mesh filename="coacd_convex_piece_3.obj" scale="1.0000E+00 1.0000E+00 1.0000E+00"/>
      </geometry>
      <material name="">
        <color rgba="7.50E-01 7.50E-01 7.50E-01 1"/>
      </material>
    </visual>
    <collision>
      <origin xyz="0 0 0" rpy="0 0 0"/>
      <geometry>
        <mesh filename="coacd_convex_piece_3.obj" scale="1.0000E+00 1.0000E+00 1.0000E+00"/>
      </geometry>
    </collision>
    <visual>
      <origin xyz="0 0 0" rpy="0 0 0"/>
      <geometry>
        <mesh filename="coacd_convex_piece_4.obj" scale="1.0000E+00 1.0000E+00 1.0000E+00"/>
      </geometry>
      <material name="">
        <color rgba="7.50E-01 7.50E-01 7.50E-01 1"/>
      </material>
    </visual>
    <collision>
      <origin xyz="0 0 0" rpy="0 0 0"/>
      <geometry>
        <mesh filename="coacd_convex_piece_4.obj" scale="1.0000E+00 1.0000E+00 1.0000E+00"/>
      </geometry>
    </collision>
    <visual>
      <origin xyz="0 0 0" rpy="0 0 0"/>
      <geometry>
        <mesh filename="coacd_convex_piece_5.obj" scale="1.0000E+00 1.0000E+00 1.0000E+00"/>
      </geometry>
      <material name="">
        <color rgba="7.50E-01 7.50E-01 7.50E-01 1"/>
      </material>
    </visual>
    <collision>
      <origin xyz="0 0 0" rpy="0 0 0"/>
      <geometry>
        <mesh filename="coacd_convex_piece_5.obj" scale="1.0000E+00 1.0000E+00 1.0000E+00"/>
      </geometry>
    </collision>
    <visual>
      <origin xyz="0 0 0" rpy="0 0 0"/>
      <geometry>
        <mesh filename="coacd_convex_piece_6.obj" scale="1.0000E+00 1.0000E+00 1.0000E+00"/>
      </geometry>
      <material name="">
        <color rgba="7.50E-01 7.50E-01 7.50E-01 1"/>
      </material>
    </visual>
    <collision>
      <origin xyz="0 0 0" rpy="0 0 0"/>
      <geometry>
        <mesh filename="coacd_convex_piece_6.obj" scale="1.0000E+00 1.0000E+00 1.0000E+00"/>
      </geometry>
    </collision>
    <visual>
      <origin xyz="0 0 0" rpy="0 0 0"/>
      <geometry>
        <mesh filename="coacd_convex_piece_7.obj" scale="1.0000E+00 1.0000E+00 1.0000E+00"/>
      </geometry>
      <material name="">
        <color rgba="7.50E-01 7.50E-01 7.50E-01 1"/>
      </material>
    </visual>
    <collision>
      <origin xyz="0 0 0" rpy="0 0 0"/>
      <geometry>
        <mesh filename="coacd_convex_piece_7.obj" scale="1.0000E+00 1.0000E+00 1.0000E+00"/>
      </geometry>
    </collision>
    <visual>
      <origin xyz="0 0 0" rpy="0 0 0"/>
      <geometry>
        <mesh filename="coacd_convex_piece_8.obj" scale="1.0000E+00 1.0000E+00 1.0000E+00"/>
      </geometry>
      <material name="">
        <color rgba="7.50E-01 7.50E-01 7.50E-01 1"/>
      </material>
    </visual>
    <collision>
      <origin xyz="0 0 0" rpy="0 0 0"/>
      <geometry>
        <mesh filename="coacd_convex_piece_8.obj" scale="1.0000E+00 1.0000E+00 1.0000E+00"/>
      </geometry>
    </collision>
    <visual>
      <origin xyz="0 0 0" rpy="0 0 0"/>
      <geometry>
        <mesh filename="coacd_convex_piece_9.obj" scale="1.0000E+00 1.0000E+00 1.0000E+00"/>
      </geometry>
      <material name="">
        <color rgba="7.50E-01 7.50E-01 7.50E-01 1"/>
      </material>
    </visual>
    <collision>
      <origin xyz="0 0 0" rpy="0 0 0"/>
      <geometry>
        <mesh filename="coacd_convex_piece_9.obj" scale="1.0000E+00 1.0000E+00 1.0000E+00"/>
      </geometry>
    </collision>
    <visual>
      <origin xyz="0 0 0" rpy="0 0 0"/>
      <geometry>
        <mesh filename="coacd_convex_piece_10.obj" scale="1.0000E+00 1.0000E+00 1.0000E+00"/>
      </geometry>
      <material name="">
        <color rgba="7.50E-01 7.50E-01 7.50E-01 1"/>
      </material>
    </visual>
    <collision>
      <origin xyz="0 0 0" rpy="0 0 0"/>
      <geometry>
        <mesh filename="coacd_convex_piece_10.obj" scale="1.0000E+00 1.0000E+00 1.0000E+00"/>
      </geometry>
    </collision>
    <visual>
      <origin xyz="0 0 0" rpy="0 0 0"/>
      <geometry>
        <mesh filename="coacd_convex_piece_11.obj" scale="1.0000E+00 1.0000E+00 1.0000E+00"/>
      </geometry>
      <material name="">
        <color rgba="7.50E-01 7.50E-01 7.50E-01 1"/>
      </material>
    </visual>
    <collision>
      <origin xyz="0 0 0" rpy="0 0 0"/>
      <geometry>
        <mesh filename="coacd_convex_piece_11.obj" scale="1.0000E+00 1.0000E+00 1.0000E+00"/>
      </geometry>
    </collision>
    <visual>
      <origin xyz="0 0 0" rpy="0 0 0"/>
      <geometry>
        <mesh filename="coacd_convex_piece_12.obj" scale="1.0000E+00 1.0000E+00 1.0000E+00"/>
      </geometry>
      <material name="">
        <color rgba="7.50E-01 7.50E-01 7.50E-01 1"/>
      </material>
    </visual>
    <collision>
      <origin xyz="0 0 0" rpy="0 0 0"/>
      <geometry>
        <mesh filename="coacd_convex_piece_12.obj" scale="1.0000E+00 1.0000E+00 1.0000E+00"/>
      </geometry>
    </collision>
    <visual>
      <origin xyz="0 0 0" rpy="0 0 0"/>
      <geometry>
        <mesh filename="coacd_convex_piece_13.obj" scale="1.0000E+00 1.0000E+00 1.0000E+00"/>
      </geometry>
      <material name="">
        <color rgba="7.50E-01 7.50E-01 7.50E-01 1"/>
      </material>
    </visual>
    <collision>
      <origin xyz="0 0 0" rpy="0 0 0"/>
      <geometry>
        <mesh filename="coacd_convex_piece_13.obj" scale="1.0000E+00 1.0000E+00 1.0000E+00"/>
      </geometry>
    </collision>
    <visual>
      <origin xyz="0 0 0" rpy="0 0 0"/>
      <geometry>
        <mesh filename="coacd_convex_piece_14.obj" scale="1.0000E+00 1.0000E+00 1.0000E+00"/>
      </geometry>
      <material name="">
        <color rgba="7.50E-01 7.50E-01 7.50E-01 1"/>
      </material>
    </visual>
    <collision>
      <origin xyz="0 0 0" rpy="0 0 0"/>
      <geometry>
        <mesh filename="coacd_convex_piece_14.obj" scale="1.0000E+00 1.0000E+00 1.0000E+00"/>
      </geometry>
    </collision>
    <visual>
      <origin xyz="0 0 0" rpy="0 0 0"/>
      <geometry>
        <mesh filename="coacd_convex_piece_15.obj" scale="1.0000E+00 1.0000E+00 1.0000E+00"/>
      </geometry>
      <material name="">
        <color rgba="7.50E-01 7.50E-01 7.50E-01 1"/>
      </material>
    </visual>
    <collision>
      <origin xyz="0 0 0" rpy="0 0 0"/>
      <geometry>
        <mesh filename="coacd_convex_piece_15.obj" scale="1.0000E+00 1.0000E+00 1.0000E+00"/>
      </geometry>
    </collision>
  </link>
    <link name="base">
        <visual>
      <origin xyz="0 0 0" rpy="0 0 0"/>
      <geometry>
        <mesh filename="coacd_convex_piece_0.obj" scale="1.0000E-05 1.0000E-05 1.0000E-05"/>
      </geometry>
      <material name="">
        <color rgba="7.50E-01 7.50E-01 7.50E-01 1"/>
      </material>
    </visual>
    <collision>
      <origin xyz="0 0 0" rpy="0 0 0"/>
      <geometry>
        <mesh filename="coacd_convex_piece_0.obj" scale="1.0000E-05 1.0000E-05 1.0000E-05"/>
      </geometry>
    </collision>
  </link>
<!--  <link name="base1"></link>-->
<!--  <joint name="joint1" type="fixed">-->
<!--    <origin xyz="0 0 0" rpy="0 0 0"/>-->
<!--    <parent link="base"/>-->
<!--    <child link="body"/>-->
<!--  </joint>-->
  <joint name="joint_use" type="revolute">
    <origin xyz="0 0 0" rpy="0 0 0"/>
    <parent link="body"/>
    <child link="base"/>
    <axis xyz="0 0 1"/>
    <limit lower="0.00" upper="1"/>
  </joint>
</robot>
