<?xml version="1.0" encoding="utf-8"?>

<mujoco model="bottle_cap_template">
    <compiler angle="radian" meshdir="../mesh" autolimits="true"></compiler>
<!--    <option impratio="10"/>-->
<!--    <statistic extent="0.3" center="0.3 0 0"/>-->

    <worldbody>

        <body name="bottle" pos="0 0 0.0820382">
            <body name="bottle_cap" pos="0 0 0">
                <joint name="bottle:z" axis="0 0 1" damping="0.05" type="hinge" pos="0 0 0" range="0 1.571"></joint>
                <geom name="cap" mesh="core-bottle-1a7ba1f4c892e2da30711cdbdbc73924-coacd_convex_piece_0" mass="0.01" pos="0 0 0" rgba="0.3 0.6 0.6 1" type="mesh" condim="6" priority="1" friction="0.5 0.01 0.003"></geom>
            </body>

            <body name="bottle_body" pos="0 0 0">
                <geom name="coacd_convex_piece_1" mesh="core-bottle-1a7ba1f4c892e2da30711cdbdbc73924-coacd_convex_piece_1" mass="0.01" pos="0 0 0" rgba="0.6 0.2 0.2 1" type="mesh" contype="2" conaffinity="2"></geom>
                <geom name="coacd_convex_piece_2" mesh="core-bottle-1a7ba1f4c892e2da30711cdbdbc73924-coacd_convex_piece_2" mass="0.01" pos="0 0 0" rgba="0.6 0.2 0.2 1" type="mesh" contype="2" conaffinity="2"></geom>
                <geom name="coacd_convex_piece_3" mesh="core-bottle-1a7ba1f4c892e2da30711cdbdbc73924-coacd_convex_piece_3" mass="0.01" pos="0 0 0" rgba="0.6 0.2 0.2 1" type="mesh" contype="2" conaffinity="2"></geom>
            </body>
        </body>
    </worldbody>

<!--    <actuator>-->
<!--        <position name="a_cap" joint="OBJRz" ctrlrange="-7 7"/>-->
<!--    </actuator>-->

<asset><mesh name="core-bottle-1a7ba1f4c892e2da30711cdbdbc73924-coacd_convex_piece_0" file="core-bottle-1a7ba1f4c892e2da30711cdbdbc73924-coacd_convex_piece_0.obj" scale="0.1 0.1 0.1" /><mesh name="core-bottle-1a7ba1f4c892e2da30711cdbdbc73924-coacd_convex_piece_1" file="core-bottle-1a7ba1f4c892e2da30711cdbdbc73924-coacd_convex_piece_1.obj" scale="0.1 0.1 0.1" /><mesh name="core-bottle-1a7ba1f4c892e2da30711cdbdbc73924-coacd_convex_piece_2" file="core-bottle-1a7ba1f4c892e2da30711cdbdbc73924-coacd_convex_piece_2.obj" scale="0.1 0.1 0.1" /><mesh name="core-bottle-1a7ba1f4c892e2da30711cdbdbc73924-coacd_convex_piece_3" file="core-bottle-1a7ba1f4c892e2da30711cdbdbc73924-coacd_convex_piece_3.obj" scale="0.1 0.1 0.1" /></asset></mujoco>