<mujoco>
  <body name="robot0:wrist" pos="0 0 0" >
      <inertial pos="0. 0 0" quat="0.504 0.496 0.495 0.504" mass="1e-40" diaginertia="0.001 0.001 0.001"></inertial>
<!--      <geom class="D_Vizual" name="robot0:V_wrist" pos= "-0.0104 0 -0.12" mesh="wrist"></geom>-->
      <joint axis="1 0 0" damping="20" name="ARTx" pos="0 0 0" range="-0.4 0.4" type="slide" />
      <joint axis="0 1 0" damping="20" name="ARTy" pos="0 0 0" range="-0.4 0.4" type="slide" />
      <joint axis="0 0 1" damping="20" name="ARTz" pos="0 0 0" range="-0.2 1.2" type="slide" />
      <joint axis="1 0 0" damping="20" name="ARRx" pos="0 0 0" range="-2 2" />
      <joint axis="0 1 0" damping="20" name="ARRy" pos="0 0 0" range="-2 2" />
      <joint axis="0 0 1" damping="20" name="ARRz" pos="0 0 0" range="-2 2" />
<!--            <geom class="DC_Hand" name="robot0:C_wrist" type="capsule" pos="0 0 0" quat="0.707 0.707 0 0" size="0.015 0.01" rgba="0.4 0.5 0.6 0.1"></geom>-->
      <site name="S_wrist"  type="sphere" rgba="0 1 0 0.125" size="0.01" pos="0 0 0"/>
      <body name="robot0:palm">
         <site name="S_palm"  type="sphere" rgba="0 1 0 0.125" size="0.01" pos="0 0 0"/>
          <geom type="mesh" mesh="40_10_link_g_r" />

          <body name="if1" pos="0 0.045098 0.014293" quat="0.999048 -0.0436194 0 0">
      <inertial pos="0 0 0" quat="0.999987 0.00268104 0.00348413 0.00243885" mass="0.0113501" diaginertia="2.70079e-06 2.05786e-06 1.27128e-06" />
      <joint name="jif1" pos="0 0 0" axis="0 0 1" limited="true" range="-0.57 0.57" />
      <geom type="mesh" rgba="0 0 0.8 1" mesh="40_10_link_f1" />
              <site name="S_ffproximal"  type="sphere" rgba="0 1 0 0.125" size="0.01" pos="0 0 0" />
      <body name="if2" pos="0 0 0">
          <inertial pos="0 0 0" quat="0.511773 0.50721 0.488471 0.492161" mass="0.0711891" diaginertia="7.80402e-05 7.66613e-05 6.93906e-06" />
          <joint name="jif2" pos="0 0 0" axis="0 1 0" limited="true" range="-0.296 1.71" />
          <geom quat="0.499998 -0.5 -0.5 -0.500002" type="mesh" rgba="0 0 0 1" mesh="40_10_link_f2" />
          <site name="Tch_ffmiddle"  type="sphere" rgba="0 1 0 0.125" size="0.01" pos="0 0 0" />
          <body name="if3" pos="0 0 0.054" quat="0.707105 0 -0.707108 0">
              <inertial pos="0 0 0" quat="0.507214 0.511 0.481375 0.499891" mass="0.0375886" diaginertia="2.94282e-05 2.81825e-05 3.82984e-06" />
              <joint name="jif3" pos="0 0 0" axis="0 1 0" limited="true" range="-0.274 1.809" />
              <geom quat="0.707105 -0.707108 0 0" type="mesh" rgba="0 0 0.8 1" mesh="40_10_link_f3" />
              <site name="Tch_ffdistal"  type="sphere" rgba="0 1 0 0.125" size="0.01" pos="0 0 0" />
              <body name="if4" pos="0.0384 0 0">
                  <inertial pos="0.0100241 0 0" quat="0.499193 0.501834 0.498241 0.500724" mass="0.0260844" diaginertia="7.51389e-06 6.89339e-06 2.682e-06" />
                  <joint name="jif4" pos="0 0 0" axis="0 1 0" limited="true" range="-0.327 1.718" />
                  <geom quat="0.707105 -0.707108 0 0" type="mesh" rgba="0 0 0 1" mesh="40_10_link_f4" />
                  <geom pos="0.0157 0 0" quat="0.707105 -0.707108 0 0" type="mesh" rgba="1 1 1 1" mesh="40_10_link_f5" />
                  <site name="Tch_fftip"  type="sphere" rgba="0 1 0 0.125" size="0.01" pos="0 0 0" />
              </body>
          </body>
      </body>
  </body>
  <body name="mf1" pos="0 0 0.0166">
      <inertial pos="0 0 0" quat="0.999987 0.00268104 0.00348413 0.00243885" mass="0.0113501" diaginertia="2.70079e-06 2.05786e-06 1.27128e-06" />
      <joint name="jmf1" pos="0 0 0" axis="0 0 1" limited="true" range="-0.57 0.57" />
      <geom type="mesh" rgba="0 0 0.8 1" mesh="40_10_link_f1" />
      <site name="S_mfproximal"  type="sphere" rgba="0 1 0 0.125" size="0.01" pos="0 0 0" />
      <body name="mf2" pos="0 0 0">
          <inertial pos="0 0 0" quat="0.511773 0.50721 0.488471 0.492161" mass="0.0711891" diaginertia="7.80402e-05 7.66613e-05 6.93906e-06" />
          <joint name="jmf2" pos="0 0 0" axis="0 1 0" limited="true" range="-0.296 1.71" />
          <geom quat="0.499998 -0.5 -0.5 -0.500002" type="mesh" rgba="0 0 0 1" mesh="40_10_link_f2" />
          <site name="Tch_mfmiddle" type="sphere" rgba="0 1 0 0.125" size="0.01" pos="0 0 0"/>
          <body name="mf3" pos="0 0 0.054" quat="0.707105 0 -0.707108 0">
              <inertial pos="0 0 0" quat="0.507214 0.511 0.481375 0.499891" mass="0.0375886" diaginertia="2.94282e-05 2.81825e-05 3.82984e-06" />
              <joint name="jmf3" pos="0 0 0" axis="0 1 0" limited="true" range="-0.274 1.809" />
              <geom quat="0.707105 -0.707108 0 0" type="mesh" rgba="0 0 0.8 1" mesh="40_10_link_f3" />
              <site name="Tch_mfdistal"  type="sphere" rgba="0 1 0 0.125" size="0.01" pos="0 0 0" />
              <body name="mf4" pos="0.0384 0 0">
                  <inertial pos="0.0100241 0 0" quat="0.499193 0.501834 0.498241 0.500724" mass="0.0260844" diaginertia="7.51389e-06 6.89339e-06 2.682e-06" />
                  <joint name="jmf4" pos="0 0 0" axis="0 1 0" limited="true" range="-0.327 1.718" />
                  <geom quat="0.707105 -0.707108 0 0" type="mesh" rgba="0 0 0 1" mesh="40_10_link_f4" />
                  <site name="Tch_mftip"  type="sphere" rgba="0 1 0 0.125" size="0.01" pos="0  0 0." />
                  <geom pos="0.0157 0 0" quat="0.707105 -0.707108 0 0" type="mesh" rgba="1 1 1 1" mesh="40_10_link_f5" />
              </body>
          </body>
      </body>
  </body>
  <body name="pf1" pos="0 -0.045098 0.014293" quat="0.999048 0.0436194 0 0">
      <inertial pos="0 0 0" quat="0.999987 0.00268104 0.00348413 0.00243885" mass="0.0113501" diaginertia="2.70079e-06 2.05786e-06 1.27128e-06" />
      <joint name="jpf1" pos="0 0 0" axis="0 0 1" limited="true" range="-0.57 0.57" />
      <geom type="mesh" rgba="0 0 0.8 1" mesh="40_10_link_f1" />
      <site name="S_rfproximal"  type="sphere" rgba="0 1 0 0.125" size="0.01" pos="0 0 0" />
      <body name="pf2" pos="0 0 0">
          <inertial pos="0 0 0" quat="0.511773 0.50721 0.488471 0.492161" mass="0.0711891" diaginertia="7.80402e-05 7.66613e-05 6.93906e-06" />
          <joint name="jpf2" pos="0 0 0" axis="0 1 0" limited="true" range="-0.296 1.71" />
          <geom quat="0.499998 -0.5 -0.5 -0.500002" type="mesh" rgba="0 0 0 1" mesh="40_10_link_f2" />
          <site name="Tch_rfmiddle"  type="sphere" rgba="0 1 0 0.125" size="0.01" pos="0 0 0" />
          <body name="pf3" pos="0 0 0.054" quat="0.707105 0 -0.707108 0">
              <inertial pos="0 0 0" quat="0.507214 0.511 0.481375 0.499891" mass="0.0375886" diaginertia="2.94282e-05 2.81825e-05 3.82984e-06" />
              <joint name="jpf3" pos="0 0 0" axis="0 1 0" limited="true" range="-0.274 1.809" />
              <geom quat="0.707105 -0.707108 0 0" type="mesh" rgba="0 0 0.8 1" mesh="40_10_link_f3" />
              <site name="Tch_rfdistal"  type="sphere" rgba="0 1 0 0.125" size="0.01" pos="0 0 0" />
              <body name="pf4" pos="0.0384 0 0">
                  <inertial pos="0.0100241 0 0" quat="0.499193 0.501834 0.498241 0.500724" mass="0.0260844" diaginertia="7.51389e-06 6.89339e-06 2.682e-06" />
                  <joint name="jpf4" pos="0 0 0" axis="0 1 0" limited="true" range="-0.327 1.718" />
                  <geom quat="0.707105 -0.707108 0 0" type="mesh" rgba="0 0 0 1" mesh="40_10_link_f4" />
                  <site name="Tch_rftip"  type="sphere" rgba="0 1 0 0.125" size="0.01" pos="0 0 0." />
                  <geom pos="0.0157 0 0" quat="0.707105 -0.707108 0 0" type="mesh" rgba="1 1 1 1" mesh="40_10_link_f5" />
              </body>
          </body>
      </body>
  </body>

  <body name="th1" pos="-0.0182 0.016958 -0.0723" quat="0.999048 -0.0436194 0 0">
      <inertial pos="0 0 0" quat="0.482949 0.855619 -0.157215 -0.0997976" mass="0.0798099" diaginertia="5.05817e-05 4.8639e-05 1.7824e-05" />
      <joint name="jth1" pos="0 0 0" axis="0 0 -1" limited="true" range="0.36357 1.4968" />
      <geom type="mesh" rgba="0 0 0.8 1" mesh="40_10_link_t1_r" />
      <site name="S_thproximal"  type="sphere" rgba="0 1 0 0.125" size="0.01" pos="0 0 0" />
      <body name="th2" pos="0.005 0.055189 0">
          <inertial pos="0 0 0" quat="0.999987 0.00268104 0.00348413 0.00243884" mass="0.0113501" diaginertia="2.70079e-06 2.05786e-06 1.27128e-06" />
          <joint name="jth2" pos="0 0 0" axis="0 1 0" limited="true" range="-0.205043 1.13" />
          <geom quat="0.499998 -0.5 -0.5 -0.500002" type="mesh" rgba="0 0 0.8 1" mesh="40_10_link_f1" />
          <site name="Tch_thmiddle"  type="sphere" rgba="0 1 0 0.125" size="0.01" pos="0 0 0" />
          <body name="th3" pos="0 0 0">
              <inertial pos="0 0 0" quat="0.525235 0.50184 0.485539 0.486351" mass="0.0402067" diaginertia="2.1851e-05 2.02903e-05 4.2785e-06" />
              <joint name="jth3" pos="0 0 0" axis="1 0 0" limited="true" range="-0.2897 1.633" />
              <geom quat="0.499998 0.5 0.500002 0.5" type="mesh" rgba="0 0 0 1" mesh="40_10_link_t3" />
              <site name="Tch_thdistal"  type="sphere" rgba="0 1 0 0.125" size="0.01" pos="0 0 0" />
              <body name="th4" pos="0 0.051204 0">
                  <inertial pos="0 0.00908081 0" quat="0.146619 0.681349 -0.15383 0.70043" mass="0.0574044" diaginertia="2.85555e-05 2.05817e-05 1.90924e-05" />
                  <joint name="jth4" pos="0 0 0" axis="1 0 0" limited="true" range="-0.2622 1.81991" />
                  <geom quat="0.499998 0.5 0.500002 0.5" type="mesh" rgba="0 0 0.8 1" mesh="40_10_link_t4" />
                  <site name="Tch_thtip"  type="sphere" rgba="0 1 0 0.125" size="0.1" pos="0 0 0." />
                  <geom pos="0 0.0313 0" quat="0.499998 0.5 0.500002 0.5" type="mesh" rgba="1 1 1 1" mesh="40_10_link_f5" />
              </body>
          </body>
      </body>
  </body>
      </body>
  </body>

</mujoco>
